Workbook

Sheet 入力画面
A2: 担当 | B2: 竹内 悠馬 | G2: 物件名 | H2: ハーモニーテラス生野西
A3: 宛名（法人） | G3: 住所
A4: 入居者 | D4: 部屋月日数 | E4: 31 | G4: 保 証 金 | I4: 号室
A5: 項目 | B5: 金額 | D5: 駐月日数 | E5: 31 | G5: 敷 金 | H5: 0 | I5: 202
A6: 保 証 金 | B6: =H4 -> 0 | G6: 礼 金 | H6: 0
A7: 敷 金 | B7: =H5 -> 0 | G7: 家 賃 | H7: 62000
A8: 項目 | B8: 金額 | C8: 何月分 | D8: 何日から | E8: 何日分 | G8: 共 益 費 | H8: 4000
A9: 日割家 賃 | B9: =ROUNDUP(H16,0) -> 62000 | C9: 12 | D9: 1 | E9: =E4-D9+1 -> 31 | G9: 水 道 代
A10: 日割共益費 | B10: =ROUNDDOWN(H17,0) -> 4000
A11: 日割水道代 | B11: =ROUNDDOWN(H18,0) -> 0 | G11: 駐保証金
A12: 日割駐車場代 | B12: =ROUNDDOWN(H20,0) -> 0 | E12: =E5-D12 -> 31 | G12: 駐解約引
A13: 日割その他 | G13: 駐車場代
A14: 翌月家 賃 | B14: 55000
A15: 翌月共益費 | B15: 6000
A16: 翌月水道代 | G16: 日割家賃 | H16: =H7/E4*E9 -> 62000
A17: 翌月その他 | G17: 日割管理費 | H17: =H8/E4*E9 -> 4000
A18: 駐車場 保証金 | B18: =H11 -> 0 | G18: 日割水道代 | H18: =H9/E4*E9 -> 0
A19: 翌月駐車場代 | G19: 日割その他 | H19: =ROUNDUP(B13/E4*E9,0) -> 0
G20: 日割駐車場 | H20: =H13/E5*E12 -> 0
A21: 仲 介 手 数 料 | B21: =H7/2 -> 31000 | C21: 支払期日
A22: 消 費 税 | B22: =B21*0.1 -> 3100 | C22: 手付金 | D22: 0 | G22: 日割合計 | H22: =H16+H17+H18+H20 -> 66000
A23: 駐車場 手数料 | B23: =H13 -> 0 | C23: 追加金 | D23: 0
A24: 消 費 税 | B24: =B23*0.1 -> 0 | G24: 駐車場代 | H24: 駐車場税込
A25: 住 宅 保 険 | G25: =H13 -> 0 | H25: =G25*1.05 -> 0
A26: クリーニング代
A27: 鍵 交 換 代 | B27: 22000
A28: 賃貸保証料 | G28: 入居日

Sheet 見積書
M1: =NOW() -> 46176.343
B3: =IF(入力画面!B3="","",入力画面!B3)
B4: この度は、蓮産業株式会社を御利用頂き誠に有り難うございました。御契約完了まで
B5: の払い込み、ならびに必要書類を下記の通り御準備頂きますようお願い申し上げます。
B6: 尚、振り込み期日は厳守願います｡又、御不明な点が御座いましたら担当者まで御問い合わせ下さい。
E8: =E37 -> 66000 | L8: 物件名 | M8: =IF(入力画面!H2="","",入力画面!H2) -> ハーモニーテラス生野西
L9: 住 所 | M9: =IF(入力画面!H3="","",入力画面!H3) | N9: =IF(入力画面!I5="","",入力画面!I5) -> 202
E10: ギガ賃貸の場合 | F10: 一般的な不動産屋 | L10: 入居者 | M10: =IF(入力画面!B4="","",入力画面!B4) | N10: 様
B11: 敷 金 | E11: =IF(入力画面!H5="","",入力画面!H5) -> 0 | F11: =IF(入力画面!H5="","",入力画面!H5) -> 0 | L11: ＜契約条件＞
B12: 礼 金 | E12: =IF(入力画面!H6="","",入力画面!H6) -> 0 | F12: =IF(入力画面!H6="","",入力画面!H6) -> 0 | L12: 保 証 金 | M12: =IF(入力画面!H4="","",入力画面!H4)
B13: 翌 | C13: 月分 家 賃 | E13: =IF(入力画面!B9="","",入力画面!B9) -> 62000 | F13: =IF(入力画面!B9="","",入力画面!B9) -> 62000 | L13: 敷 金 | M13: =IF(入力画面!H5="","",入力画面!H5) -> 0
B14: 翌 | C14: 月分共益費 | E14: =IF(入力画面!B10="","",入力画面!B10) -> 4000 | F14: =IF(入力画面!B10="","",入力画面!B10) -> 4000 | L14: 礼 金 | M14: =IF(入力画面!H6="","",入力画面!H6) -> 0
L15: 家 賃 | M15: =IF(入力画面!H7="","",入力画面!H7) -> 62000
L16: 共 益 費 | M16: =IF(入力画面!H8="","",入力画面!H8) -> 4000
L17: 町 会 費
L18: 月額保証料
L19: 駐保証金 | M19: =IF(入力画面!H11="","",入力画面!H11)
L20: その他
B25: 抗菌施工費 | E25: 16500 | F25: 16500
B26: 賃貸保証料(保証人有) | E26: 30000 | F26: 30000
B27: 火災保険 | E27: 18000 | F27: 18000
B28: 仲介手数料 | E28: 0 | F28: =IF(入力画面!B9="","",入力画面!B9) -> 62000
B29: 消費税 | F29: =F28*0.1 -> 6200
B30: ギガ割 | E30: -64500
B32: 計 | E32: =SUM(E10:E31) -> 66000 | F32: =SUM(F11:J31) -> 198700
B35: ギガ割 | E35: =E30 -> -64500
B37: 差引請求金額 | E37: =E32-E34-E36 -> 66000
D39: 上記金額を | F39: 迄に御振込下さい。
D40: 尚、御振込については、 にてお願い致します。
D41: 誠に恐縮ですが、振込手数料は御負担下さい。
D43: 〒541-0048 | E43: 大阪市中央区瓦町3-4-10
E44: 日宝御堂ビル5F

Sheet 請求書
M1: =NOW() -> 46176.343
B3: =IF(入力画面!B3="","",入力画面!B3)
B4: この度は、(株)アールを御利用頂き誠に有り難うございました。御契約完了まで
B5: の払い込み、ならびに必要書類を下記の通り御準備頂きますようお願い申し上げます。
B6: 尚、振り込み期日は厳守願います｡又、御不明な点が御座いましたら担当者まで御問い合わせ下さい。
E8: =E37 -> 191965 | L8: 物件名 | M8: =IF(入力画面!H2="","",入力画面!H2) -> ハーモニーテラス生野西
L9: 住 所 | M9: =IF(入力画面!H3="","",入力画面!H3) | N9: =IF(入力画面!I5="","",入力画面!I5) -> 202
E10: =IF(入力画面!H4="","",入力画面!H4) | L10: 入居者 | M10: =IF(入力画面!B4="","",入力画面!B4) | N10: 様
B11: 敷 金 | E11: =IF(入力画面!H5="","",入力画面!H5) -> 0 | L11: ＜契約条件＞
B12: 礼 金 | E12: =IF(入力画面!H6="","",入力画面!H6) -> 0 | L12: 保 証 金 | M12: =IF(入力画面!H4="","",入力画面!H4)
B13: 11 | C13: 月分 家 賃 | E13: =IF(入力画面!B9="","",入力画面!B9) -> 62000 | F13: =IF(入力画面!D9="","",入力画面!D9) -> 1 | G13: ～ | H13: （ | I13: =IF(入力画面!E9="","",入力画面!E9) -> 31 | J13: ）日分 | L13: 敷 金 | M13: =IF(入力画面!H5="","",入力画面!H5) -> 0
B14: 11 | C14: 月分共益費 | E14: 4065 | F14: =IF(入力画面!D9="","",入力画面!D9) -> 1 | G14: ～ | H14: （ | I14: =IF(入力画面!E9="","",入力画面!E9) -> 31 | J14: ）日分 | L14: 礼 金 | M14: =IF(入力画面!H6="","",入力画面!H6) -> 0
H15: （ | J15: ）日分 | L15: 家 賃 | M15: =IF(入力画面!H7="","",入力画面!H7) -> 62000
L16: 共 益 費 | M16: =IF(入力画面!H8="","",入力画面!H8) -> 4000
B17: =B13+1 -> 12 | C17: 月分 家 賃 | E17: =IF(入力画面!B14="","",入力画面!B14) -> 55000 | L17: 町 会 費 | M17: =IF(入力画面!H9="","",入力画面!H9)
B18: =B14+1 -> 12 | C18: 月分共益費 | E18: =IF(入力画面!B15="","",入力画面!B15) -> 6000 | M18: =IF(入力画面!H10="","",入力画面!H10)
E19: =IF(入力画面!B16="","",入力画面!B16) | L19: 駐保証金 | M19: =IF(入力画面!H11="","",入力画面!H11)
L20: 駐 車 場 | M20: =IF(入力画面!H13="","",入力画面!H13)
B24: 仲介手数料 | E24: 0 | F24: 御紹介割引
B27: ファイテック契約費用 | E27: 6600
B28: 住 宅 保 険 | E28: 別途支払い | F28: 18,000円/2年毎
B29: 安心入居サポート | E29: 16500
B30: 防虫消毒費 | E30: 19800 | F30: 初回のみ
B31: 賃貸保証料 | E31: 22000
B32: 計 | E32: =SUM(E10:E31) -> 191965
B35: 手 付 金 | E35: 0
B36: 追 加 金 | E36: =IF(入力画面!D23="","",入力画面!D23) -> 0
B37: 差引請求金額 | E37: =E32-E34-E36-E35 -> 191965
D39: 上記金額を | E39: 44839 | F39: 迄に御振込下さい。
D40: 尚、御振込については、 にてお願い致します。
D41: 誠に恐縮ですが、振込手数料は御負担下さい。
D43: 〒542-0086 | E43: 大阪市中央区西心斎橋2丁目9番38号
E44: おおきに心斎橋LAND MARKビル1階

Sheet 広告料請求書
D1: 請 求 書
G4: 請求日 | H4: =NOW() -> 46176.343
A5: 株式会社
C6: 御中
G8: 〒542-0086
G9: 大阪市中央区西心斎橋2-9-38
G10: おおきにＬＡＮＤ ＭＡＲＫ心斎橋ビル1階
G11: 株式会社ユニティエール
G12: TEL：06-6484-0300
A13: 下記のとおりご請求申し上げます。 | G13: FAX：06-6484-0400
G14: 担当：貴志 任
A16: 日付 | B16: 請求項目 | H16: 金額
A17: =NOW() -> 46176.343 | B17: =IF(入力画面!H2="","",入力画面!H2) -> ハーモニーテラス生野西 | F17: の広告料として
H19: =IF(B19="","",#REF!*#REF!)
H20: =IF(B20="","",#REF!*#REF!)
H21: =IF(B21="","",#REF!*#REF!)
H22: =IF(B22="","",#REF!*#REF!)
H23: =IF(B23="","",#REF!*#REF!)
H24: =IF(B24="","",#REF!*#REF!)
H25: =IF(B25="","",#REF!*#REF!)
H26: =IF(B26="","",#REF!*#REF!)
D29: 請求合計額 | G29: =SUM(H17:I26) -> 0
B33: << お振込先 >>
B34: 関西みらい銀行･心斎橋営業部 普通口座 0012789 株式会社ユニティエール カ)ユニティエール

Sheet 引越しの流れ
B2: 必要書類とお引越しまでの手順
B4: この度は、賃貸くんでのご契約誠にありがとうございます。
B5: 下記に契約に必要な書類の説明とお引越しまでの手順をお知らせいたします。ご不明な点がございましたら担当までご連絡下さい。
C8: 必要書類 | Q8: 左記の必要書類は契約書と一緒にお持ち下さい。ご郵送の場合は、配達証明つきでご郵送
C9: 住民票 | K9: 契約者 | N9: 1 | O9: 通 | Q9: くださいますようお願いいたします。
C10: 顔写真 | K10: 契約者 | N10: 1 | O10: 枚
C11: 源泉徴収票 | K11: 契約者 | N11: 1 | O11: 通 | Q11: ■契約書にご記入いただく際の注意点として、ご記入いただく契約書の住所は公的証明と合わ
C12: 印鑑証明書 | K12: 連帯保証人 | N12: 1 | O12: 通 | Q12: てご記入下さい。住民票記載の住所、印鑑証明書記載の住所でのご記入となります。
C13: 源泉徴収票 | K13: 連帯保証人 | N13: 1 | O13: 通 | Q13: ■契約書は、必ずご本人がご記入下さい。契約者が全て記入してしまうケースがございますが
Q14: 訂正しやり直す必要が出ます。また、誤って記入してしまった。間違ってしまった場合は、次
Q15: のように訂正してください。
Q16: 誤り 正しい
Q18: ■契約者は基本認印での捺印ですが、印鑑証明書を求められる際は実印にてご捺印下さい。
Q19: 連帯保証人が必要な契約は、保証人欄は全て実印にてご捺印下さい。
C22: ① | E22: お申し込み | K22: / | Q22: お申込書を記入頂きます。またお申込金として家賃の１か月分をお預かりいたします。
C25: ② | E25: 入居審査 | K25: / | Q25: お申し込みいただきました書類より、家主様・管理会社・賃貸保証会社などへ連絡し審査を
Q26: 行います。審査結果が出た段階にてご連絡させていただきます。
Q27: ※審査承認まで2日～一週間ほどかかります。承認が出ましたらご連絡お願い致します。
C28: ③ | E28: 重要事項説明 | K28: / | Q28: 契約書が届きましたら、店頭にてご記入・ご捺印いただくか郵送サービスも行っております。
Q29: 上記の契約記入の注意点もご確認下さい。
Q30: ※契約書郵送時もご連絡致します。
C31: ④ | E31: 決済金支払 | K31: / | Q31: 契約書をご確認の上、お支払いをお願いいたします。契約手続きの都合上先にお支払い
Q32: 頂くこともございます。ご了承下さい。
Q33: ※振り込みされましたら、一報ご連絡頂ければ幸いです。
C34: ⑤ | E34: 契約書記入 | K34: / | Q34: 上記必要書類と契約書に記入・捺印の上、弊社までお届け下さい。
C37: ⑥ | E37: 契約書期日 | K37: / | Q37: お引越しするのに必要な手続きはたくさんございますが、ライフラインは重要ですので
Q38: お早めにご連絡とお手続きをお願いいたします。
Q39: ※ライフラインの開栓は審査終了後で有れば手続き可能です。
C40: ⑦ | E40: 鍵のお渡し | K40: / | Q40: 鍵が手配できましたら、ご連絡させていただきます。
Q41: お支払・契約書の不備・必要書類の不備があった場合には鍵がお渡しできないこともご
Q42: ざいますので、手続きはお早めにお願いいたします。

Sheet ライフライン
B6: ご契約誠にありがとうございます。
A9: 区 | C9: 区役所 | F9: 警察署 | I9: 関西電力 | J9: 大阪ガス | K9: 水道局
A10: 中央区 | C10: 6267-9986 | D10: 久太郎1-2-27 | E10: 南6281-1234 | G10: 東心斎橋1-5-26 | I10: 0800-777-8012 | J10: 0120-094-817 ※事前予約必須 | K10: 06-6458-1132
E11: 東6268-1234 | G11: 本町1-3-18 | I11: 0800-777-8021
A12: 天王寺区 | C12: 6774-9986 | D12: 真法院町20-33 | E12: 6913-1234 | G12: 六万体5-8 | I12: 0800-777-8012
I13: 0800-777-8021
A14: 生野区 | C14: 6715-9986 | D14: 勝山南3-1-19 | E14: 6712-1234 | G14: 勝山北3-14-12 | I14: 0800-777-8022
I15: 0800-777-8023
A16: 東成区 | C16: 6977-9986 | D16: 大今里西2-4-8 | E16: 6974-1234 | G16: 大今里西1-25-15 | I16: 0800-777-8012
A17: 北区 | C17: 6313-9986 | D17: 扇町2-1-27 | E17: 6376-1234 | G17: 中津1-5-25 | I17: 0800-777-8012
A18: 城東区 | C18: 6930-9986 | D18: 中央3-4-29 | E18: 6934-1234 | G18: 中央1-9-38 | I18: 0800-777-8012
A19: 阿倍野区 | C19: 6622-9986 | D19: 文の里1-1-40 | E19: 6653-1234 | G19: 阿倍野5-13-5 | I19: 0800-777-8022
A20: 西区 | C20: 6532-9625 | D20: 新町4-5-14 | E20: 6583-1234 | G20: 川口2-6-3 | I20: 0800-777-8011
A21: 浪速区 | C21: 6647-9986 | D21: 難波中3-11-16 | E21: 6633-1234 | G21: 日本橋5-5-11 | I21: 0800-777-8021
A22: 旭区 | C22: 6957-9986 | D22: 大宮1-1-17 | E22: 6952-1234 | G22: 大宮5-12-20 | I22: 0800-777-8016
A23: 鶴見区 | C23: 6915-9986 | D23: 横堤5-4-19 | E23: 6913-1234 | G23: 諸口6-1-1 | I23: 0800-777-8012
I24: 0800-777-8016
A25: 都島区 | C25: 6882-9986 | D25: 中野2-16-20 | E25: 6925-1234 | G25: 都島北1-7-1 | I25: 0800-777-8012
A26: 住之江区 | C26: 6682-9986 | D26: 御崎3-1-17 | E26: 6682-1234 | G26: 新北島3-1-24 | I26: 0800-777-8021
A27: 住吉区 | C27: 6694-9986 | D27: 殿辻1-8-18 | E27: 6675-1234 | G27: 東粉浜3-28-3 | I27: 0800-777-8022
I28: 0800-777-8021
A29: 大正区 | C29: 4394-9986 | D29: 千島2-7-95 | E29: 6555-1234 | G29: 小林東3-4-21 | I29: 0800-777-8011
A30: 西成区 | C30: 6659-9986 | D30: 岸里1-1-64 | E30: 6648-1234 | G30: 萩之茶屋2-4-2 | I30: 0800-777-8021
A31: 東住吉区 | C31: 4399-9986 | D31: 東田辺1-13-4 | E31: 6697-1234 | G31: 東田辺2-11-39 | I31: 0800-777-8022
A32: 平野区 | C32: 4302-9986 | D32: 平野西3-5-5 | E32: 6794-1234 | G32: 平野元町5-20 | I32: 0800-777-8022
A33: 港区 | C33: 6576-9986 | D33: 市岡1-15-25 | E33: 6574-1234 | G33: 市岡1-6-22 | I33: 0800-777-8011
A34: 此花区 | C34: 6466-9986 | D34: 春日出北1-8-4 | E34: 6466-1234 | G34: 春日出北1-3-2 | I34: 0800-777-8011
A35: 西淀川区 | C35: 6478-9986 | D35: 御幣島1-2-10 | E35: 6474-1234 | G35: 千船2-6-24 | I35: 0800-777-8011
A36: 淀川区 | C36: 6308-9986 | D36: 十三東1-18-21 | E36: 6305-1234 | G36: 十三本町3-7-27 | I36: 0800-777-8014
A37: 東淀川区 | C37: 4809-9986 | D37: 豊新2-1-4 | E37: 6325-1234 | G37: 豊新1-6-18 | I37: 0800-777-8015
A38: 福島区 | C38: 6464-9986 | D38: 吉野3-17-23 | E38: 6465-1234 | G38: 吉野4-9-19 | I38: 0800-777-8011
A40: ライフライン開栓・接続時の注意事項
B43: 借主届出 | D43: 開栓・接続手続き | F43: 立会い | H43: ※備考 | J43: 注意点
A44: 電気 | B44: 入居時に使用者番号を電話 | D44: 各自建物内のブレーカー | F44: 基本的に不要です | H44: 通常指定用紙が玄関ドア上部に | J44: オール電化マンションは、開栓時にその旨
B45: 連絡ください。建物内に使用 | D45: を上げてください。 | F45: 但し不通状態の際には | H45: 吊り下がっています。 | J45: を関西電力にお伝えください。また電気給湯
B46: 番号記載の用紙があります。 | D46: ◎各自で行います。 | F46: 要立会いになります。 | H46: （赤色のはがき位の大きさ） | J46: 器は開栓後電源を入れ、しばらくしないと、
J47: お湯が使用できません。
A48: 水道 | B48: 基本的に不要です。 | D48: 基本的に開栓済です。 | F48: 基本的に不要です | H48: 開栓手続き不要の場合がほとん
B49: 物件・地域によっては申込金 | D49: 停止状態の際は止水栓を | H49: どですが、念の為水道局に連絡
B50: 等必要な場合もあります。 | D50: 開けてください。 | H50: するようにしてください。
...

Sheet 付帯申込書
A1: 各提携業者様 各位 御担当者様
B3: 優良提携業者 依頼 申込書
A6: 入居希望日 | D6: 入居予定日 月 日
A8: 物 | B8: 名称 | I8: 号室
A10: 件 | B10: 新住所
B12: フリガナ
A13: お | B13: 氏名
A14: 客
A15: 様 | B15: 現住所
A16: 情
A17: 報 | B17: ＴＥＬ | G17: 生年月日 | H17: 年 | I17: 月 | J17: 日
B18: 携帯 | G18: 性別 | H18: 男 ・ 女
A19: 【 ご連絡のつきやすい曜日・日時・時間帯 】 該当項目にチェックをいれてください。
B20: □ | D20: 月 ・ 火 ・ 水 ・ 木 ・ 金 ・ 土 ・ 日
B22: □ | D22: 月 日 時 ～ 時
A25: 【 お引越し 】 当社提携引越業者様割引！ 当店にパンフレットあります！！
A27: □ アイズ引越プランニング | F27: □ アート引越センター
A29: ＴＥＬ 0120 - 09 - 1103 | F29: TEL 0120 - 81 - 0123
A30: ＦＡＸ 075 - 382 - 0447 | F30: FAX 0120 - 00 - 5670
A31: 【 特記事項 】
A38: 【 インターネット 】 当社の通信事業部からご連絡させていただきます！
C40: 回線設備担当 岡澤 070-5372-3896
A42: 【 特記事項 】
A47: 提携業者様にご依頼いただき、お預かりする情報については厳重に管理し、目的以外の用途には使用しません。
A50: 【 取次店 】 | C50: 〒542-0081 大阪市中央区西心斎橋 2-9-38 ウィナックス 1Ｆ
C53: ＴＥＬ 06-6484-0300 | F53: ＦＡＸ 06-6484-0400

Sheet お届け明細書
B1: ＜お届け明細書＞
X6: 殿
A9: 物件名 | G9: =IF(入力画面!H2="","",入力画面!H2) -> ハーモニーテラス生野西 | X9: =IF(入力画面!I5="","",入力画面!I5) -> 202 | AA9: 号室
A10: 契約者名 | G10: =IF(入力画面!B3="","",入力画面!B3) | X10: 様
A12: 差引お届け金額 | K12: =K37 -> 149000
AC14: ＜契約条件＞
A16: 保証金(敷金･礼金) | K16: =SUM(AF16:AK18) -> 0 | AB16: 保証金 | AF16: =IF(入力画面!H4="","",入力画面!H4) | AL16: 円
AB17: 敷金 | AF17: =IF(入力画面!H5="","",入力画面!H5) -> 0 | AL17: 円
A18: =IF(入力画面!C9="","",入力画面!C9) -> 12 | C18: 月分日割家賃 | K18: =IF(入力画面!B9="","",入力画面!B9) -> 62000 | AB18: 礼金 | AF18: =IF(入力画面!H6="","",入力画面!H6) -> 0 | AL18: 円
A19: =IF(入力画面!C9="","",入力画面!C9) -> 12 | C19: 月分日割共益費 | K19: =IF(入力画面!B10="","",入力画面!B10) -> 4000 | AB19: 解約引 | AF19: =IF(入力画面!H10="","",入力画面!H10) | AL19: 円
A20: =IF(入力画面!C9="","",入力画面!C9) -> 12 | C20: 月分日割水道代 | K20: =IF(入力画面!B11="","",入力画面!B11) -> 0 | AB20: 家賃 | AF20: =IF(入力画面!H7="","",入力画面!H7) -> 62000 | AL20: 円
AB21: 共益費 | AF21: =IF(入力画面!H8="","",入力画面!H8) -> 4000 | AL21: 円
A22: =A18+1 -> 13 | C22: 月分 家賃 | K22: =IF(入力画面!B14="","",入力画面!B14) -> 55000 | AB22: 水道代 | AF22: =IF(入力画面!H9="","",入力画面!H9) | AL22: 円
A23: =A19+1 -> 13 | C23: 月分 共益費 | K23: =IF(入力画面!B15="","",入力画面!B15) -> 6000 | AB23: 駐車場代 | AF23: =IF(入力画面!H13="","",入力画面!H13) | AL23: 円
A24: =A20+1 -> 13 | C24: 月分 水道代 | K24: =IF(入力画面!B16="","",入力画面!B16)
A26: 住宅保険料 | K26: =IF(入力画面!B25="","",入力画面!B25)
A27: 賃貸保証料 | K27: =IF(入力画面!B28="","",入力画面!B28)
A28: 鍵交換代 | K28: =IF(入力画面!B27="","",入力画面!B27) -> 22000
A31: 合計金額 | K31: =SUM(K16:S30) -> 149000
D33: 手付金 | K33: ▲
D34: 中間金 | K34: ▲
D35: 広告料 | K35: ▲
B37: 差引後金額 | K37: =K31-M33-M34-M35 -> 149000 | AA37: 貴志 | AI37: 貴志

Sheet 鍵受領書
D1: 受領書
J4: 令和 年 月 日
B6: 物件名 | J6: 号室
C9: 賃貸借契約書お控え | J9: 部
C12: 賃貸保証契約書お控え | J12: 部
C15: 火災保険書類お控え | J15: 部
C24: 鍵 | D24: メーカー | G24: ＮＯ． | K24: 本数
C25: 1 | K25: 本
C32: 上記、正に預かりました。
I34: 氏名 | M34: ㊞
